Workbook

Sheet Menu
A1: 2024
H11: Frankfur
C63: €23.7 | G63: €23.7 | K63: €23.7 | O63: €23.7
F64: Barlow CondensedBarlow Condensed | J64: Barlow CondensedBarlow Condensed | N64: Barlow CondensedBarlow Condensed
C66: NET SALES | G66: NET SALES | K66: NET SALES | O66: NET SALES
F67: Net Sales | J67: Net Sales | N67: Net Sales

Sheet Performance
C14: FY 2021 | P14: FY 2022
C17: IDEAL | P17: RISKY BUT COMMON
B20: 0.07 | C20: 0.07 | D20: =IF('Financial Statements'!B$41>0,"WC>0","WC<0") -> WC>0 | G20: =IF('Financial Statements'!B$42>0,"WCN>0","WCN<0") -> WCN>0 | J20: =IF('Financial Statements'!B$43>0,"NC>0","NC<0") -> NC>0 | O20: 0.17 | Q20: =IF('Financial Statements'!C$41>0,"WC>0","WC<0") -> WC>0 | T20: =IF('Financial Statements'!C$42>0,"WCN>0","WCN<0") -> WCN>0 | W20: =IF('Financial Statements'!C$43>0,"NC>0","NC<0") -> NC<0
C24: INTERPRETATION | P24: INTERPRETATION
C26: Healthy cycle. Long-term resources cover fixed assets with extra cash for operations. | P26: Stable long-term, but short-term liquidity tension. Operating cycle too heavy, needs short-term bank loans.
C32: FY 2023 | P32: FY 2024
C35: IDEAL | P35: IDEAL
B38: 2 | D38: =IF('Financial Statements'!E$41>0,"WC>0","WC<0") -> WC>0 | G38: =IF('Financial Statements'!E$42>0,"WCN>0","WCN<0") -> WCN>0 | J38: =IF('Financial Statements'!E$43>0,"NC>0","NC<0") -> NC>0 | O38: 18 | Q38: =IF('Financial Statements'!G$41>0,"WC>0","WC<0") -> WC>0 | T38: =IF('Financial Statements'!G$42>0,"WCN>0","WCN<0") -> WCN>0 | W38: =IF('Financial Statements'!G$43>0,"NC>0","NC<0") -> NC>0
C42: INTERPRETATION | P42: INTERPRETATION
C44: Healthy cycle. Long-term resources cover fixed assets with extra cash for operations. | P44: Healthy cycle. Long-term resources cover fixed assets with extra cash for operations.
C69: LIQUIDITY | P69: SOLVENCY & LEVERAGE
C72: CURRENT RATIO | P72: TOTAL DEBT RATIO
C75: INTERPRETATION | P75: INTERPRETATION
C76: The Current Ratio has been mostly declining over 2021–2024 (20.2% ↓), moving from Healthy (1.56) to adequate but tight (1.24) in 2024. | P76: The Total Debt Ratio has been mostly improving over 2021–2024 (15.0% ↑), from Low–moderate debt (0.27) to Low–moderate debt (0.31) in 2024.
C77: QUICK & CASH RATIO | P77: D/E RATIO & EQUITY MULTIPLIER
C80: INTERPRETATION | P80: INTERPRETATION
C81: In 2024, the Quick Ratio stands at 0.72 Risky and the Cash Ratio at 0.22 Below ideal. | P81: In 2024, the D/E ratio of 1.09 signals Acceptable, and the Equity Multiplier of 3.52 indicates High leverage. In 2024, the Quick Ratio stands at 0.72 Risky and the Cash Ratio at 0.22 Below ideal.
C87: FINANCIAL STRUCTURE | P87: SCISSORS EFFECT
C90: WC/WCN/NC | P90: CURRENT RATIO
C93: INTERPRETATION | P93: INTERPRETATION
C94: Adidas followed the scenario path Case 1 → Case 2 → Case 1 → Case 1, from Case 1 Ideal in 2021 to Case 1 deal in 2024. In 2024: WC Positive (€2,311.0M), WCN Positive (€1,358.0M), NC Positive (€953.0M), and Net Debt of €4,241.0M. | P94: The Current Ratio has been mostly declining over 2021–2024 (20.2% ↓), moving from Healthy (1.56) to adequate but tight (1.24) in 2024.
P95: CURRENT RATIO
P98: INTERPRETATION
P99: The Current Ratio has been mostly declining over 2021–2024 (20.2% ↓), moving from Healthy (1.56) to adequate but tight (1.24) in 2024. In 2024, the Quick Ratio stands at 0.72 Risky and the Cash Ratio at 0.22 Below ideal.

Sheet Profitability
C15: ROE | P15: ROS
C18: ='Financial Statements'!I7 -> 0.23199446 | P18: ='Financial Statements'!I8 -> 0.054008303
B21: 0.14 | C21: =IF(B21>0,"+"&B21,B21)&"% vs 2021" -> +0,14% vs 2021 | O21: -0.14 | P21: =IF(O21>0,"+"&O21,O21)&"% vs 2021" -> -0,14% vs 2021
B22: 0.001 | O22: 0.001
B35: 0.07 | O35: 0.07
C43: ASSETS TURNOVER | P43: EQUITY MULTIPLIER
C46: ='Financial Statements'!I9 -> 1.2245089 | P46: ='Financial Statements'!I10 -> 3.507964
B49: -0.12 | C49: =IF(B49>0,"+"&B49,B49)&"% vs 2021" -> -0,12% vs 2021 | O49: 0.13 | P49: =IF(O49>0,"+"&O49,O49)&"% vs 2021" -> +0,13% vs 2021
B63: 0.07 | O63: 0.07

Sheet Investment management
C15: DSO | P15: DIO
C18: ='Financial Statements'!I19 -> 38.749345 | P18: ='Financial Statements'!I20 -> 177.28658
B21: 0.14 | C21: =IF(B21>0,"+"&B21,B21)&"% vs 2021" -> +0,14% vs 2021 | O21: -0.14 | P21: =IF(O21>0,"+"&O21,O21)&"% vs 2021" -> -0,14% vs 2021
B22: 0.001 | O22: 0.001
B35: 0.07 | O35: 0.07
C43: DPO | P43: CCC
C46: ='Financial Statements'!I21 -> 88.460898 | P46: ='Financial Statements'!I22 -> 127.57503
B49: -0.12 | C49: =IF(B49>0,"+"&B49,B49)&"% vs 2021" -> -0,12% vs 2021 | O49: 0.13 | P49: =IF(O49>0,"+"&O49,O49)&"% vs 2021" -> +0,13% vs 2021
B63: 0.07 | O63: 0.07
J75: PPE TURNOVER
J78: ='Financial Statements'!I24 -> 5.4196156
I81: 0.13 | J81: =IF(I81>0,"+"&I81,I81)&"% vs 2021" -> +0,13% vs 2021
I95: 0.07

Sheet Operating Management
C15: GROSS PROFIT MARGIN | P15: EBITDA
C18: ='Financial Statements'!I14 -> 0.51606142 | P18: ='Financial Statements'!I15 -> 3124000
B21: 0.014 | C21: =IF(B21>0,"+"&B21,B21)&"% vs 2021" -> +0,014% vs 2021 | O21: 0.5 | P21: =IF(O21>0,"+"&O21,O21)&"% vs 2021" -> +0,5% vs 2021
B22: 0.001 | O22: 0.001
B35: 0.07 | O35: 0.07
C43: EBITDA MARGIN | P43: EBIT MARGIN
C46: ='Financial Statements'!I16 -> 0.12591189 | P46: ='Financial Statements'!I17 -> 0.083027689
B49: 0.07 | C49: =IF(B49>0,"+"&B49,B49)&"% vs 2021" -> +0,07% vs 2021 | O49: 0.07 | P49: =IF(O49>0,"+"&O49,O49)&"% vs 2021" -> +0,07% vs 2021
B63: 0.07 | O63: 0.07

Sheet Financial management 
C15: CURRENT RATIO | P15: QUICK RATIO
C18: ='Financial Statements'!I26 -> 1.3170571 | P18: ='Financial Statements'!I27 -> 0.67568459
B21: -0.12 | C21: =IF(B21>0,"+"&B21,B21)&"% vs 2021" -> -0,12% vs 2021 | O21: 0.13 | P21: =IF(O21>0,"+"&O21,O21)&"% vs 2021" -> +0,13% vs 2021
B35: 0.07 | O35: 0.07
J43: CASH RATIO
J46: ='Financial Statements'!I28 -> 0.1778291
I49: 0.13 | J49: =IF(I49>0,"+"&I49,I49)&"% vs 2021" -> +0,13% vs 2021
I63: 0.07
C77: D/E RATIO | P77: TOTAL DEBT RATIO
C80: ='Financial Statements'!I30 -> 1.089162 | P80: ='Financial Statements'!I31 -> 0.31048268
B83: -0.12 | C83: =IF(B83>0,"+"&B83,B83)&"% vs 2021" -> -0,12% vs 2021 | O83: 0.13 | P83: =IF(O83>0,"+"&O83,O83)&"% vs 2021" -> +0,13% vs 2021
B97: 0.07 | O97: 0.07
C105: INTEREST COVERAGE | P105: NET DEBT/EBITDA
C108: ='Financial Statements'!I32 -> 7.1280277 | P108: ='Financial Statements'!I33 -> 1.4961588
B111: 0.14 | C111: =IF(B111>0,"+"&B111,B111)&"% vs 2021" -> +0,14% vs 2021 | O111: -0.14 | P111: =IF(O111>0,"+"&O111,O111)&"% vs 2021" -> -0,14% vs 2021
B112: 0.001 | O112: 0.001
B125: 0.07 | O125: 0.07

Sheet Ratio for investors shareholder
C15: DIVIDEND PAYOUT | P15: DIVIDEND YIELD
C18: ='Financial Statements'!I35 -> 0.26641791 | P18: ='Financial Statements'!I36 -> 0.010356892
B21: 0.14 | C21: =IF(B21>0,"+"&B21,B21)&"% vs 2021" -> +0,14% vs 2021 | O21: -0.14 | P21: =IF(O21>0,"+"&O21,O21)&"% vs 2021" -> -0,14% vs 2021
B22: 0.001 | O22: 0.001
B35: 0.07 | O35: 0.07
C43: EPS | P43: P/E RATIO
C46: ='Financial Statements'!I37 -> 7.5027996 | P46: ='Financial Statements'!I38 -> 25.723731
B49: -0.12 | C49: =IF(B49>0,"+"&B49,B49)&"% vs 2021" -> -0,12% vs 2021 | O49: 0.13 | P49: =IF(O49>0,"+"&O49,O49)&"% vs 2021" -> +0,13% vs 2021
B63: 0.07 | O63: 0.07
J71: P/B RATIO
J74: ='Financial Statements'!I39 -> 5.9677632
I77: 0.13 | J77: =IF(I77>0,"+"&I77,I77)&"% vs 2021" -> +0,13% vs 2021
I91: 0.07

Sheet SFS
C15: WORKING CAPITAL | P15: WORKING CAPITAL NEEDED
C18: ='Financial Statements'!I41 -> 2533000 | P18: ='Financial Statements'!I42 -> 2514000
B21: -0.12 | C21: =IF(B21>0,"+"&B21,B21)&"% vs 2021" -> -0,12% vs 2021 | O21: 0.13 | P21: =IF(O21>0,"+"&O21,O21)&"% vs 2021" -> +0,13% vs 2021
B35: 0.07 | O35: 0.07
C43: NET CASH | P43: CAPITAL EMPLOYED
C46: ='Financial Statements'!I43 -> 19000 | P46: ='Financial Statements'!I44 -> 9.946
B49: 0.14 | C49: =IF(B49>0,"+"&B49,B49)&"% vs 2021" -> +0,14% vs 2021 | O49: -0.14 | P49: =IF(O49>0,"+"&O49,O49)&"% vs 2021" -> -0,14% vs 2021
B50: 0.001 | O50: 0.001
B63: 0.07 | O63: 0.07
C71: INVESTED CAPITAL | P71: NET DEBT
C74: ='Financial Statements'!I45 -> 9.946 | P74: ='Financial Statements'!I46 -> 4674000
B77: -0.12 | C77: =IF(B77>0,"+"&B77,B77)&"% vs 2021" -> -0,12% vs 2021 | O77: 0.13 | P77: =IF(O77>0,"+"&O77,O77)&"% vs 2021" -> +0,13% vs 2021
B91: 0.07 | O91: 0.07
C99: ENTREPRISE VALUE | P99: EV/EBITDA
C102: ='Financial Statements'!I47 -> 39143800 | P102: ='Financial Statements'!I48 -> 12.530026
B105: 0.14 | C105: =IF(B105>0,"+"&B105,B105)&"% vs 2021" -> +0,14% vs 2021 | O105: -0.14 | P105: =IF(O105>0,"+"&O105,O105)&"% vs 2021" -> -0,14% vs 2021
B106: 0.001 | O106: 0.001
B119: 0.07 | O119: 0.07
J127: NET DEBT/EBITDA
J130: ='Financial Statements'!I49 -> 1.4961588
I133: 0.13 | J133: =IF(I133>0,"+"&I133,I133)&"% vs 2021" -> +0,13% vs 2021
I147: 0.07

Sheet Financial Statements
A5: RATIO ANALYSIS | B5: 2021 | C5: 2022 | D5: Trend N-1 | E5: 2023 | F5: Trend N-1 | G5: 2024 | H5: Trend N-1 | I5: 2025 | J5: Trend N-1 | K5: Level of the Key indicator | Q5: Balance Sheet | R5: 2021 | S5: Common-size | T5: 2022 | U5: Common-size | V5: Trend N-1 | W5: 2023 | X5: Common-size | Y5: Trend N-1 | Z5: 2024 | AA5: Common-size | AB5: Trend N-1 | AC5: 2025 | AD5: Common-size | AE5: Trend N-1
A6: Profitability analysis
A7: ROE | B7: =R52/R21 -> 0.27000128 | C7: =S52/T21 -> 0.11437115 | D7: =C7/B7-1 -> -0.57640517 | E7: =U52/W21 -> -0.015228426 | F7: =E7/C7-1 -> -1.1331492 | G7: =W52/Z21 -> 0.13019768 | H7: =G7/E7-1 -> -9.5496478 | I7: =Y52/AC21 -> 0.23199446 | J7: =I7/G7-1 -> 0.78186321 | K7: <5% | L7: 5%>>>10% | M7: 10%>>15% | N7: >15% check debt | Q7: Intangible assets | R7: 1581000 | S7: =IFERROR(R7/$R$30,"N/A") -> 0.071418891 | T7: 1689000 | U7: =IFERROR(T7/$T$16, "N/A") -> 0.083222469 | V7: =IFERROR(T7/R7-1,"N/A") -> 0.068311195 | W7: 1680000 | X7: =IFERROR(W7/$W$30,"N/A") -> 0.093229745 | Y7: =IFERROR(W7/T7-1,"N/A") -> -0.0053285968 | Z7: 1701000 | AA7: =IFERROR(Z7/$Z$16,"N/A") -> 0.082352941 | AB7: =IFERROR(Z7/W7-1,"N/A") -> 0.0125 | AC7: 1646000 | AD7: =IFERROR(AC7/$AC$16,"N/A") -> 0.081235811 | AE7: =IFERROR(AC7/Z7-1,"N/A") -> -0.032333921
A8: ROS | B8: =R52/R34 -> 0.099651502 | C8: =S52/S34 -> 0.027186709 | D8: =C8/B8-1 -> -0.72718215 | E8: =U52/U34 -> -0.0035002567 | F8: =E8/C8-1 -> -1.1287488 | G8: =W52/W34 -> 0.032259427 | H8: =G8/E8-1 -> -10.216303 | I8: =Y52/Y34 -> 0.054008303 | J8: =I8/G8-1 -> 0.67418669 | K8: <5% | L8: 5%>>>10% | M8: 10%>>15% | N8: >15% sector( Retail / Lux) | Q8: Property, plant and equipment | R8: 4825000 | S8: =IFERROR(R8/$R$30,"N/A") -> 0.21796088 | T8: 4943000 | U8: =IFERROR(T8/$T$16, "N/A") -> 0.24355753 | V8: =IFERROR(T8/R8-1,"N/A") -> 0.024455959 | W8: 4405000 | X8: =IFERROR(W8/$W$30,"N/A") -> 0.24445061 | Y8: =IFERROR(W8/T8-1,"N/A") -> -0.10884078 | Z8: 4912000 | AA8: =IFERROR(Z8/$Z$16,"N/A") -> 0.23781167 | AB8: =IFERROR(Z8/W8-1,"N/A") -> 0.11509648 | AC8: 4578000 | AD8: =IFERROR(AC8/$AC$16,"N/A") -> 0.22594018 | AE8: =IFERROR(AC8/Z8-1,"N/A") -> -0.067996743
A9: Assets turnover | B9: =R34/R16 -> 0.95920856 | C9: =S34/T16 -> 1.1091895 | D9: =C9/B9-1 -> 0.156359 | E9: =U34/W16 -> 1.1890677 | F9: =E9/C9-1 -> 0.072014971 | G9: =W34/Z16 -> 1.1465989 | H9: =G9/E9-1 -> -0.035716062 | I9: =Y34/AC16 -> 1.2245089 | J9: =I9/G9-1 -> 0.067948825 | K9: <0,5 | L9: 0,5<<<<1 | M9: 1<<<<<2 | N9: >2 | Q9: Other non-current assets | R9: 1787000 | S9: =IFERROR(R9/$R$30,"N/A") -> 0.080724579 | T9: 1931000 | U9: =IFERROR(T9/$T$16, "N/A") -> 0.095146588 | V9: =IFERROR(T9/R9-1,"N/A") -> 0.080581981 | W9: 2126000 | X9: =IFERROR(W9/$W$30,"N/A") -> 0.11798002 | Y9: =IFERROR(W9/T9-1,"N/A") -> 0.10098395 | Z9: 2138000 | AA9: =IFERROR(Z9/$Z$16,"N/A") -> 0.10351005 | AB9: =IFERROR(Z9/W9-1,"N/A") -> 0.0056444026 | AC9: 2062000 | AD9: =IFERROR(AC9/$AC$16,"N/A") -> 0.10176685 | AE9: =IFERROR(AC9/Z9-1,"N/A") -> -0.03554724
A10: Equity Multiplier | B10: =R16/R21 -> 2.8246778 | C10: =T16/T21 -> 3.792749 | E10: =W16/W21 -> 3.6588832 | F10: =E10/C10-1 -> -0.035295183 | G10: =Z16/Z21 -> 3.5199387 | H10: =G10/E10-1 -> -0.037974592 | I10: =AC16/AC21 -> 3.507964 | J10: =I10/G10-1 -> -0.0034019517 | K10: >4 risk | L10: 2,5<<<<4 | M10: 1,5<<<2,5 | N10: <1,5 safe | Q10: Total non-current assets | R10: 8193000 | S10: =IFERROR(R10/$R$30,"N/A") -> 0.37010435 | T10: 8563000 | U10: =IFERROR(T10/$T$16, "N/A") -> 0.42192658 | V10: =IFERROR(T10/R10-1,"N/A") -> 0.045160503 | W10: 8211000 | X10: =IFERROR(W10/$W$30,"N/A") -> 0.45566038 | Y10: =IFERROR(W10/T10-1,"N/A") -> -0.041107089 | Z10: 8751000 | AA10: =IFERROR(Z10/$Z$16,"N/A") -> 0.42367466 | AB10: =IFERROR(Z10/W10-1,"N/A") -> 0.065765437 | AC10: =AC7+AC8+AC9 -> 8286000 | AD10: =IFERROR(AC10/$AC$16,"N/A") -> 0.40894285 | AE10: =IFERROR(AC10/Z10-1,"N/A") -> -0.053136784
A11: ROE decomposition: Traditional approach | Q11: Inventories | R11: 4009000 | S11: =IFERROR(R11/$R$30,"N/A") -> 0.18109952 | T11: 5973000 | U11: =IFERROR(T11/$T$16, "N/A") -> 0.29430894 | V11: =IFERROR(T11/R11-1,"N/A") -> 0.48989773 | W11: 4525000 | X11: =IFERROR(W11/$W$30,"N/A") -> 0.25110988 | Y11: =IFERROR(W11/T11-1,"N/A") -> -0.24242424 | Z11: 4989000 | AA11: =IFERROR(Z11/$Z$16,"N/A") -> 0.24153958 | AB11: =IFERROR(Z11/W11-1,"N/A") -> 0.10254144 | AC11: 5832000 | AD11: =IFERROR(AC11/$AC$16,"N/A") -> 0.28782943 | AE11: =IFERROR(AC11/Z11-1,"N/A") -> 0.16897174
A12: ROE = ROS x Assets turnover x Eq, Multiplier | B12: =B8*B9*B10 -> 0.27000128 | C12: =C8*C9*C10 -> 0.11437115 | D12: =C12/B12-1 -> -0.57640517 | E12: =E8*E9*E10 -> -0.015228426 | F12: =E12/C12-1 -> -1.1331492 | G12: =G8*G9*G10 -> 0.13019768 | H12: =G12/E12-1 -> -9.5496478 | I12: =I8*I9*I10 -> 0.23199446 | J12: =I12/G12-1 -> 0.78186321 | K12: <5% | L12: 5%>>>10% | M12: 10%>>15% | N12: >15% check debt | Q12: Accounts receivable | R12: 3015000 | S12: =IFERROR(R12/$R$30,"N/A") -> 0.13619732 | T12: 1862000 | U12: =IFERROR(T12/$T$16, "N/A") -> 0.091746736 | V12: =IFERROR(T12/R12-1,"N/A") -> -0.38242123 | W12: 2903000 | X12: =IFERROR(W12/$W$30,"N/A") -> 0.16109878 | Y12: =IFERROR(W12/T12-1,"N/A") -> 0.55907626 | Z12: 3145000 | AA12: =IFERROR(Z12/$Z$16,"N/A") -> 0.15226337 | AB12: =IFERROR(Z12/W12-1,"N/A") -> 0.083362039 | AC12: 2634000 | AD12: =IFERROR(AC12/$AC$16,"N/A") -> 0.12999704 | AE12: =IFERROR(AC12/Z12-1,"N/A") -> -0.16248013
A13: Operating management: Profit margins | Q13: Other current assets | R13: 3092000 | S13: =IFERROR(R13/$R$30,"N/A") -> 0.13967566 | T13: 3099000 | U13: =IFERROR(T13/$T$16, "N/A") -> 0.15269771 | V13: =IFERROR(T13/R13-1,"N/A") -> 0.0022639069 | W13: 1161000 | X13: =IFERROR(W13/$W$30,"N/A") -> 0.064428413 | Y13: =IFERROR(W13/T13-1,"N/A") -> -0.62536302 | Z13: 1640000 | AA13: =IFERROR(Z13/$Z$16,"N/A") -> 0.079399661 | AB13: =IFERROR(Z13/W13-1,"N/A") -> 0.41257537 | AC13: 1893000 | AD13: =IFERROR(AC13/$AC$16,"N/A") -> 0.093426118 | AE13: =IFERROR(AC13/Z13-1,"N/A") -> 0.15426829
A14: Gross profit margin | B14: =R36/R34 -> 0.50696995 | C14: =S36/S34 -> 0.4728355 | D14: =C14/B14-1 -> -0.067330324 | E14: =U36/U34 -> 0.47524152 | F14: =E14/C14-1 -> 0.0050884823 | G14: =W36/W34 -> 0.50774817 | H14: =G14/E14-1 -> 0.068400287 | I14: =Y36/Y34 -> 0.51606142 | J14: =I14/G14-1 -> 0.016372783 | K14: <20% | L14: 20%<<40% | M14: 40%<<60% | N14: >60% Luxe & software | Q14: Cash and cash equivalents | R14: 3828000 | S14: =IFERROR(R14/$R$30,"N/A") -> 0.17292316 | T14: 798000 | U14: =IFERROR(T14/$T$16, "N/A") -> 0.03932003 | V14: =IFERROR(T14/R14-1,"N/A") -> -0.79153605 | W14: 1220000 | X14: =IFERROR(W14/$W$30,"N/A") -> 0.067702553 | Y14: =IFERROR(W14/T14-1,"N/A") -> 0.52882206 | Z14: 2130000 | AA14: =IFERROR(Z14/$Z$16,"N/A") -> 0.10312273 | AB14: =IFERROR(Z14/W14-1,"N/A") -> 0.74590164 | AC14: 1617000 | AD14: =IFERROR(AC14/$AC$16,"N/A") -> 0.07980456 | AE14: =IFERROR(AC14/Z14-1,"N/A") -> -0.24084507
A15: EBITDA (in £m/€m) | B15: =R42 -> 3066000 | C15: =S42 -> 1874000 | D15: =C15/B15-1 -> -0.38878017 | E15: =U42 -> 1358000 | F15: =E15/C15-1 -> -0.27534685 | G15: =W42 -> 2465000 | H15: =G15/E15-1 -> 0.81516937 | I15: =Y42 -> 3124000 | J15: =I15/G15-1 -> 0.2673428 | Q15: Total current assets | R15: 13944000 | S15: =IFERROR(R15/$R$30,"N/A") -> 0.62989565 | T15: 11732000 | U15: =IFERROR(T15/$T$16, "N/A") -> 0.57807342 | V15: =IFERROR(T15/R15-1,"N/A") -> -0.15863454 | W15: 9809000 | X15: =IFERROR(W15/$W$30,"N/A") -> 0.54433962 | Y15: =IFERROR(W15/T15-1,"N/A") -> -0.16391067 | Z15: 11904000 | AA15: =IFERROR(Z15/$Z$16,"N/A") -> 0.57632534 | AB15: =IFERROR(Z15/W15-1,"N/A") -> 0.21357937 | AC15: =AC11+AC12+AC13+AC14 -> 11976000 | AD15: =IFERROR(AC15/$AC$16,"N/A") -> 0.59105715 | AE15: =IFERROR(AC15/Z15-1,"N/A") -> 0.0060483871
A16: EBITDA margin | B16: =R42/R34 -> 0.14439107 | C16: =S42/S34 -> 0.08324819 | D16: =C16/B16-1 -> -0.42345334 | E16: =U42/U34 -> 0.063377981 | F16: =E16/C16-1 -> -0.23868638 | G16: =W42/W34 -> 0.1040831 | H16: =G16/E16-1 -> 0.6422596 | I16: =Y42/Y34 -> 0.12591189 | J16: =I16/G16-1 -> 0.2097247 | K16: <10% | L16: 10%<<<20% | M16: 20%<<<30% | N16: >30% | Q16: Total assets | R16: 22137000 | S16: =IFERROR(R16/$R$30,"N/A") -> 1 | T16: 20295000 | U16: =IFERROR(T16/$T$16, "N/A") -> 1 | V16: =IFERROR(T16/R16-1,"N/A") -> -0.083209107 | W16: 18020000 | X16: =IFERROR(W16/$W$30,"N/A") -> 1 | Y16: =IFERROR(W16/T16-1,"N/A") -> -0.11209658 | Z16: 20655000 | AA16: =IFERROR(Z16/$Z$16,"N/A") -> 1 | AB16: =IFERROR(Z16/W16-1,"N/A") -> 0.14622642 | AC16: =AC10+AC15 -> 20262000 | AD16: =IFERROR(AC16/$AC$16,"N/A") -> 1 | AE16: =IFERROR(AC16/Z16-1,"N/A") -> -0.01902687
A17: Operating profit (or EBIT) margin | B17: =R44/R34 -> 0.093670528 | C17: =S44/S34 -> 0.029718804 | D17: =C17/B17-1 -> -0.68273047 | E17: =U44/U34 -> 0.012507584 | F17: =E17/C17-1 -> -0.57913569 | G17: =W44/W34 -> 0.056453997 | H17: =G17/E17-1 -> 3.5135813 | I17: =Y44/Y34 -> 0.083027689 | J17: =I17/G17-1 -> 0.47071411 | Q17: Issued share capital | R17: 192000 | S17: =IFERROR(R17/$R$30,"N/A") -> 0.008673262 | T17: 179000 | U17: =IFERROR(T17/$T$16, "N/A") -> 0.0088199064 | V17: =IFERROR(T17/R17-1,"N/A") -> -0.067708333 | W17: 179000 | X17: =IFERROR(W17/$W$30,"N/A") -> 0.0099334073 | Y17: =IFERROR(W17/T17-1,"N/A") -> 0 | Z17: 179000 | AA17: =IFERROR(Z17/$Z$16,"N/A") -> 0.0086661825 | AB17: =IFERROR(Z17/W17-1,"N/A") -> 0 | AC17: 179000 | AD17: =IFERROR(AC17/$AC$16,"N/A") -> 0.008834271 | AE17: =IFERROR(AC17/Z17-1,"N/A") -> 0
A18: Investment management: Working capital management | Q18: Capital & Other reserves | R18: 785000 | S18: =IFERROR(R18/$R$30,"N/A") -> 0.035460993 | T18: 825000 | U18: =IFERROR(T18/$T$16, "N/A") -> 0.040650407 | V18: =IFERROR(T18/R18-1,"N/A") -> 0.050955414 | W18: 601000 | X18: =IFERROR(W18/$W$30,"N/A") -> 0.033351831 | Y18: =IFERROR(W18/T18-1,"N/A") -> -0.27151515 | Z18: 914000 | AA18: =IFERROR(Z18/$Z$16,"N/A") -> 0.044250787 | AB18: =IFERROR(Z18/W18-1,"N/A") -> 0.52079867 | AC18: -161000 | AD18: =IFERROR(AC18/$AC$16,"N/A") -> -0.0079459086 | AE18: =IFERROR(AC18/Z18-1,"N/A") -> -1.1761488
A19: Days' receivables | B19: =R12*365/R34 -> 51.826081 | C19: =T12*365/S34 -> 30.191018 | D19: =C19/B19-1 -> -0.41745513 | E19: =W12*365/U34 -> 49.451393 | F19: =E19/C19-1 -> 0.63795052 | G19: =Z12*365/W34 -> 48.470422 | H19: =G19/E19-1 -> -0.019837081 | I19: =AC12*365/Y34 -> 38.749345 | J19: =I19/G19-1 -> -0.20055688 | K19: >60 | L19: 40<<<<60 | M19: 30<<<<40 | N19: <30 | Q19: Equity portion of convertible debt | R19: - | S19: =IFERROR(R19/$R$30,"N/A") -> N/A | T19: - | U19: =IFERROR(T19/$T$16, "N/A") -> N/A | V19: =IFERROR(T19/R19-1,"N/A") -> N/A | W19: - | X19: =IFERROR(W19/$W$30,"N/A") -> N/A | Y19: =IFERROR(W19/T19-1,"N/A") -> N/A | Z19: - | AA19: =IFERROR(Z19/$Z$16,"N/A") -> N/A | AB19: =IFERROR(Z19/W19-1,"N/A") -> N/A | AC19: 0 | AD19: =IFERROR(AC19/$AC$16,"N/A") -> 0 | AE19: =IFERROR(AC19/Z19-1,"N/A") -> N/A
A20: Days' inventories | B20: =R11*365/R35 -> 139.77314 | C20: =T11*365/S35 -> 183.71492 | D20: =C20/B20-1 -> 0.31437932 | E20: =W11*365/U35 -> 146.88945 | F20: =E20/C20-1 -> -0.20044899 | G20: =Z11*365/W35 -> 156.20046 | H20: =G20/E20-1 -> 0.063387881 | I20: =AC11*365/Y35 -> 177.28658 | J20: =I20/G20-1 -> 0.13499396 | K20: >60 | L20: 40<<<<60 | M20: 30<<<<40 | N20: <30 | Q20: Retained earnings | R20: 6860000 | S20: =IFERROR(R20/$R$30,"N/A") -> 0.30988842 | T20: 4347000 | U20: =IFERROR(T20/$T$16, "N/A") -> 0.21419069 | V20: =IFERROR(T20/R20-1,"N/A") -> -0.36632653 | W20: 4145000 | X20: =IFERROR(W20/$W$30,"N/A") -> 0.2300222 | Y20: =IFERROR(W20/T20-1,"N/A") -> -0.046468829 | Z20: 4775000 | AA20: =IFERROR(Z20/$Z$16,"N/A") -> 0.23117889 | AB20: =IFERROR(Z20/W20-1,"N/A") -> 0.15199035 | AC20: 5758000 | AD20: =IFERROR(AC20/$AC$16,"N/A") -> 0.28417728 | AE20: =IFERROR(AC20/Z20-1,"N/A") -> 0.20586387
A21: Days' payables | B21: =R25*365/R35 -> 79.979941 | C21: =T25*365/S35 -> 89.442993 | D21: =C21/B21-1 -> 0.11831782 | E21: =W25*365/U35 -> 73.88296 | F21: =E21/C21-1 -> -0.17396593 | G21: =Z25*365/W35 -> 96.932578 | H21: =G21/E21-1 -> 0.31197476 | I21: =AC25*365/Y35 -> 88.460898 | J21: =I21/G21-1 -> -0.087397661 | K21: <30 | L21: 30<<<<40 | M21: 40<<<<60 | N21: >60 (Commercial law) | Q21: Total equity | R21: 7837000 | S21: =IFERROR(R21/$R$30,"N/A") -> 0.35402268 | T21: 5351000 | U21: =IFERROR(T21/$T$16, "N/A") -> 0.263661 | V21: =IFERROR(T21/R21-1,"N/A") -> -0.31721322 | W21: 4925000 | X21: =IFERROR(W21/$W$30,"N/A") -> 0.27330744 | Y21: =IFERROR(W21/T21-1,"N/A") -> -0.079611288 | Z21: 5868000 | AA21: =IFERROR(Z21/$Z$16,"N/A") -> 0.28409586 | AB21: =IFERROR(Z21/W21-1,"N/A") -> 0.19147208 | AC21: =AC17+AC18+AC19+AC20 -> 5776000 | AD21: =IFERROR(AC21/$AC$16,"N/A") -> 0.28506564 | AE21: =IFERROR(AC21/Z21-1,"N/A") -> -0.015678255
A22: CCC | B22: =B19+B20-B21 -> 111.61928 | C22: =C19+C20-C21 -> 124.46295 | D22: =C22/B22-1 -> 0.11506676 | E22: =E19+E20-E21 -> 122.45789 | F22: =E22/C22-1 -> -0.016109717 | G22: =G19+G20-G21 -> 107.73831 | H22: =G22/E22-1 -> -0.12020115 | I22: =I19+I20-I21 -> 127.57503 | J22: =I22/G22-1 -> 0.1841195 | K22: >90 | L22: 30<<<<90 | M22: 0<<<<<30 | N22: <0 high the better | Q22: Borrowings & similar liabilities (interest-bearing) | R22: 4729000 | S22: =IFERROR(R22/$R$30,"N/A") -> 0.21362425 | T22: 5289000 | U22: =IFERROR(T22/$T$16, "N/A") -> 0.26060606 | V22: =IFERROR(T22/R22-1,"N/A") -> 0.11841827 | W22: 4469000 | X22: =IFERROR(W22/$W$30,"N/A") -> 0.24800222 | Y22: =IFERROR(W22/T22-1,"N/A") -> -0.15503876 | Z22: 4410000 | AA22: =IFERROR(Z22/$Z$16,"N/A") -> 0.21350763 | AB22: =IFERROR(Z22/W22-1,"N/A") -> -0.013202059 | AC22: 4306000 | AD22: =IFERROR(AC22/$AC$16,"N/A") -> 0.21251604 | AE22: =IFERROR(AC22/Z22-1,"N/A") -> -0.023582766
A23: Investment management: Non-current asset management | Q23: Other non-current liabilities | R23: 606000 | S23: =IFERROR(R23/$R$30,"N/A") -> 0.027374983 | T23: 399000 | U23: =IFERROR(T23/$T$16, "N/A") -> 0.019660015 | V23: =IFERROR(T23/R23-1,"N/A") -> -0.34158416 | W23: 583000 | X23: =IFERROR(W23/$W$30,"N/A") -> 0.032352941 | Y23: =IFERROR(W23/T23-1,"N/A") -> 0.46115288 | Z23: 784000 | AA23: =IFERROR(Z23/$Z$16,"N/A") -> 0.037956911 | AB23: =IFERROR(Z23/W23-1,"N/A") -> 0.34476844 | AC23: 737000 | AD23: =IFERROR(AC23/$AC$16,"N/A") -> 0.036373507 | AE23: =IFERROR(AC23/Z23-1,"N/A") -> -0.05994898
A24: PP&E turnover | B24: =R34/R8 -> 4.400829 | C24: =S34/T8 -> 4.5541169 | D24: =C24/B24-1 -> 0.0348316 | E24: =U34/W8 -> 4.8642452 | F24: =E24/C24-1 -> 0.068098437 | G24: =W34/Z8 -> 4.8214577 | H24: =G24/E24-1 -> -0.0087963332 | I24: =Y34/AC8 -> 5.4196156 | J24: =I24/G24-1 -> 0.12406163 | K24: <0,5 | L24: 0,5<<<<<1 | M24: 1<<<<<<2 | N24: >2 and Check | Q24: Total non-current liabilities | R24: 5335000 | S24: =IFERROR(R24/$R$30,"N/A") -> 0.24099923 | T24: 5688000 | U24: =IFERROR(T24/$T$16, "N/A") -> 0.28026608 | V24: =IFERROR(T24/R24-1,"N/A") -> 0.066166823 | W24: 5052000 | X24: =IFERROR(W24/$W$30,"N/A") -> 0.28035516 | Y24: =IFERROR(W24/T24-1,"N/A") -> -0.11181435 | Z24: 5194000 | AA24: =IFERROR(Z24/$Z$16,"N/A") -> 0.25146454 | AB24: =IFERROR(Z24/W24-1,"N/A") -> 0.02810768 | AC24: =AC22+AC23 -> 5043000 | AD24: =IFERROR(AC24/$AC$16,"N/A") -> 0.24888955 | AE24: =IFERROR(AC24/Z24-1,"N/A") -> -0.029072006
A25: Financial management: Liquidity analysis | Q25: Accounts payable | R25: =2294000 -> 2294000 | S25: =IFERROR(R25/$R$30,"N/A") -> 0.10362741 | T25: 2908000 | U25: =IFERROR(T25/$T$16, "N/A") -> 0.14328652 | V25: =IFERROR(T25/R25-1,"N/A") -> 0.26765475 | W25: 2276000 | X25: =IFERROR(W25/$W$30,"N/A") -> 0.12630411 | Y25: =IFERROR(W25/T25-1,"N/A") -> -0.2173315 | Z25: 3096000 | AA25: =IFERROR(Z25/$Z$16,"N/A") -> 0.14989107 | AB25: =IFERROR(Z25/W25-1,"N/A") -> 0.3602812 | AC25: =2910000 -> 2910000 | AD25: =IFERROR(AC25/$AC$16,"N/A") -> 0.1436186 | AE25: =IFERROR(AC25/Z25-1,"N/A") -> -0.060077519
A26: Current ratio | B26: =R15/R29 -> 1.555382 | C26: =T15/T29 -> 1.2673652 | D26: =C26/B26-1 -> -0.18517432 | E26: =W15/W29 -> 1.2195698 | F26: =E26/C26-1 -> -0.037712432 | G26: =Z15/Z29 -> 1.2409048 | H26: =G26/E26-1 -> 0.017493885 | I26: =AC15/AC29 -> 1.3170571 | J26: =I26/G26-1 -> 0.061368325 | K26: below 1 | L26: 1>>>>1,5 | M26: 1,5>>>2 | N26: >>>3 ??? Check | Q26: Bank overdraft (interest-bearing) | R26: - | S26: =IFERROR(R26/$R$30,"N/A") -> N/A | T26: - | U26: =IFERROR(T26/$T$16, "N/A") -> N/A | V26: =IFERROR(T26/R26-1,"N/A") -> N/A | W26: - | X26: =IFERROR(W26/$W$30,"N/A") -> N/A | Y26: =IFERROR(W26/T26-1,"N/A") -> N/A | Z26: - | AA26: =IFERROR(Z26/$Z$16,"N/A") -> N/A | AB26: =IFERROR(Z26/W26-1,"N/A") -> N/A | AD26: =IFERROR(AC26/$AC$16,"N/A") -> 0 | AE26: =IFERROR(AC26/Z26-1,"N/A") -> N/A
A27: Quick ratio | B27: =(R15-R11)/R29 -> 1.1081985 | C27: =(T15-T11)/T29 -> 0.6221238 | D27: =C27/B27-1 -> -0.43861703 | E27: =(W15-W11)/W29 -> 0.65696879 | F27: =E27/C27-1 -> 0.056009744 | G27: =(Z15-Z11)/Z29 -> 0.72083811 | H27: =G27/E27-1 -> 0.097218192 | I27: =(AC15-AC11)/AC29 -> 0.67568459 | J27: =I27/G27-1 -> -0.062640304 | K27: below 1 | L27: 0,5>>>>1 | M27: 1>>>1,5 | N27: >>>2 ??? Check | Q27: Borrowings & similar liabilities (interest-bearing) | R27: 602000 | S27: =IFERROR(R27/$R$30,"N/A") -> 0.02719429 | T27: 1170000 | U27: =IFERROR(T27/$T$16, "N/A") -> 0.057649667 | V27: =IFERROR(T27/R27-1,"N/A") -> 0.94352159 | W27: 1094000 | X27: =IFERROR(W27/$W$30,"N/A") -> 0.060710322 | Y27: =IFERROR(W27/T27-1,"N/A") -> -0.064957265 | Z27: 1177000 | AA27: =IFERROR(Z27/$Z$16,"N/A") -> 0.056983781 | AB27: =IFERROR(Z27/W27-1,"N/A") -> 0.075868373 | AC27: 1248000 | AD27: =IFERROR(AC27/$AC$16,"N/A") -> 0.06159313 | AE27: =IFERROR(AC27/Z27-1,"N/A") -> 0.060322855
A28: Cash ratio | B28: =R14/R29 -> 0.42699387 | C28: =T14/T29 -> 0.086205034 | D28: =C28/B28-1 -> -0.79811177 | E28: =W14/W29 -> 0.15168469 | F28: =E28/C28-1 -> 0.75958048 | G28: =Z14/Z29 -> 0.2220369 | H28: =G28/E28-1 -> 0.46380558 | I28: =AC14/AC29 -> 0.1778291 | J28: =I28/G28-1 -> -0.19910115 | K28: Below 0 | L28: below 0,5 | M28: 0,5>>>1 | N28: Higher is better | Q28: Other current liabilities | R28: =8363000-2294000 -> 6069000 | S28: =IFERROR(R28/$R$30,"N/A") -> 0.27415639 | T28: =8087000-2908000 -> 5179000 | U28: =IFERROR(T28/$T$16, "N/A") -> 0.25518601 | V28: =IFERROR(T28/R28-1,"N/A") -> -0.14664689 | W28: =6949000-2276000 -> 4673000 | X28: =IFERROR(W28/$W$30,"N/A") -> 0.25932297 | Y28: =IFERROR(W28/T28-1,"N/A") -> -0.097702259 | Z28: =8416000-3096000 -> 5320000 | AA28: =IFERROR(Z28/$Z$16,"N/A") -> 0.25756475 | AB28: =IFERROR(Z28/W28-1,"N/A") -> 0.13845495 | AC28: =7845000-2910000 -> 4935000 | AD28: =IFERROR(AC28/$AC$16,"N/A") -> 0.24355937 | AE28: =IFERROR(AC28/Z28-1,"N/A") -> -0.072368421
A29: Financial management: Solvency analysis | Q29: Total current liabilities | R29: 8965000 | S29: =IFERROR(R29/$R$30,"N/A") -> 0.40497809 | T29: 9257000 | U29: =IFERROR(T29/$T$16, "N/A") -> 0.4561222 | V29: =IFERROR(T29/R29-1,"N/A") -> 0.03257111 | W29: 8043000 | X29: =IFERROR(W29/$W$30,"N/A") -> 0.4463374 | Y29: =IFERROR(W29/T29-1,"N/A") -> -0.131144 | Z29: 9593000 | AA29: =IFERROR(Z29/$Z$16,"N/A") -> 0.4644396 | AB29: =IFERROR(Z29/W29-1,"N/A") -> 0.19271416 | AC29: =AC27+AC28+AC25 -> 9093000 | AD29: =IFERROR(AC29/$AC$16,"N/A") -> 0.4487711 | AE29: =IFERROR(AC29/Z29-1,"N/A") -> -0.052121338
A30: Debt to equity | B30: =(R24+R27)/R21 -> 0.75756029 | C30: =(T24+T27)/T21 -> 1.2816296 | D30: =C30/B30-1 -> 0.69178561 | E30: =(W24+W27)/W21 -> 1.2479188 | F30: =E30/C30-1 -> -0.026303091 | G30: =(Z24+Z27)/Z21 -> 1.0857192 | H30: =G30/E30-1 -> -0.12997611 | I30: =(AC24+AC27)/AC21 -> 1.089162 | J30: =I30/G30-1 -> 0.0031710734 | K30: <0,6 | L30: 0,4<<<0,6 | M30: 0,2<<<0,4 | N30: <0 high the better | Q30: Total equity and liabilities | R30: 22137000 | S30: =IFERROR(R30/$R$30,"N/A") -> 1 | T30: 20296000 | U30: =IFERROR(T30/$T$16, "N/A") -> 1.0000493 | V30: =IFERROR(T30/R30-1,"N/A") -> -0.083163934 | W30: 18020000 | X30: =IFERROR(W30/$W$30,"N/A") -> 1 | Y30: =IFERROR(W30/T30-1,"N/A") -> -0.11214032 | Z30: 20655000 | AA30: =IFERROR(Z30/$Z$16,"N/A") -> 1 | AB30: =IFERROR(Z30/W30-1,"N/A") -> 0.14622642 | AC30: =AC21+AC24+AC29 -> 19912000 | AD30: =IFERROR(AC30/$AC$16,"N/A") -> 0.98272629 | AE30: =IFERROR(AC30/Z30-1,"N/A") -> -0.03597192
A31: Total debt ratio | B31: =(R24+R27)/R16 -> 0.26819352 | C31: =(T24+T27)/T16 -> 0.33791574 | D31: =C31/B31-1 -> 0.25996982 | E31: =(W24+W27)/W16 -> 0.34106548 | F31: =E31/C31-1 -> 0.009321081 | G31: =(Z24+Z27)/Z16 -> 0.30844832 | H31: =G31/E31-1 -> -0.095633146 | I31: =(AC24+AC27)/AC16 -> 0.31048268 | J31: =I31/G31-1 -> 0.0065954626 | K31: >1,5 | L31: 1<<<<1,5 | M31: 0,5<<<<1 | N31: <0,5
A32: Interest coverage | B32: =R44/-R46 -> 11.563953 | C32: =S44/-S46 -> 2.9866071 | D32: =C32/B32-1 -> -0.74173131 | E32: =U44/-U46 -> 1.2761905 | F32: =E32/C32-1 -> -0.57269557 | G32: =W44/-W46 -> 5.96875 | H32: =G32/E32-1 -> 3.6770056 | I32: =Y44/-Y46 -> 7.1280277 | J32: =I32/G32-1 -> 0.19422453 | K32: <1,5 | L32: 1,5<<<<3 | M32: 3<<<<<5 | N32: >5 | Q32: Income Statement | R32: 2021 | S32: 2022 | T32: Trend N-1 | U32: 2023 | V32: Trend N-1 | W32: 2024 | X32: Trend N-1 | Y32: 2025 | Z32: Trend N-1
A33: Net Debt-to-EBITDA | B33: =B46/B15 -> 0.68786693 | C33: =C46/C15 -> 3.2337247 | D33: =C33/B33-1 -> 3.7010905 | E33: =E46/E15 -> 3.6273932 | F33: =E33/C33-1 -> 0.12173843 | G33: =G46/G15 -> 1.7204868 | H33: =G33/E33-1 -> -0.52569608 | I33: =I46/I15 -> 1.4961588 | J33: =I33/G33-1 -> -0.13038638 | K33: >3 | L33: 2<<<<<3 | M33: 1<<<<<2 | N33: <1
A34: Ratio for investors/shareholders | Q34: Revenue (Net Sales) | R34: 21234000 | S34: 22511000 | T34: =IFERROR(S34/R34-1,"N/A") -> 0.060139399 | U34: 21427000 | V34: =IFERROR(U34/S34-1,"N/A") -> -0.048154236 | W34: 23683000 | X34: =IFERROR(W34/U34-1,"N/A") -> 0.10528772 | Y34: 24811000 | Z34: =IFERROR(Y34/W34-1,"N/A") -> 0.047629101
A35: Dividend payout ratio | B35: =R97/R52 -> 0.24858223 | C35: =S97/S52 -> 0.96405229 | D35: =C35/B35-1 -> 2.8782027 | E35: =T97/U52 -> -1.6666667 | F35: =E35/C35-1 -> -2.7288136 | G35: =U97/W52 -> 0.16361257 | H35: =G35/E35-1 -> -1.0981675 | I35: =V97/Y52 -> 0.26641791 | J35: =I35/G35-1 -> 0.62834627 | K35: 0<<<0,3 | L35: 0,3<<<0,5 | M35: 0,5<<<0,6 | N35: >0,6 | Q35: Cost of Sales | R35: 10469000 | S35: 11867000 | T35: =IFERROR(S35/R35-1,"N/A") -> 0.13353711 | U35: 11244000 | V35: =IFERROR(U35/S35-1,"N/A") -> -0.052498525 | W35: 11658000 | X35: =IFERROR(W35/U35-1,"N/A") -> 0.036819637 | Y35: 12007000 | Z35: =IFERROR(Y35/W35-1,"N/A") -> 0.029936524
A36: Dividend yield | B36: =R98/R96 -> 0.0095004154 | C36: =S98/S96 -> 0.026026158 | D36: =C36/B36-1 -> 1.7394758 | E36: =T98/T96 -> 0.0037852979 | F36: =E36/C36-1 -> -0.85455795 | G36: =U98/U96 -> 0.0029178338 | H36: =G36/E36-1 -> -0.22916667 | I36: =V98/V96 -> 0.010356892 | J36: =I36/G36-1 -> 2.5495141 | K36: <1% | L36: 1%<<<3% | M36: 3%<<<6% | N36: >6% | Q36: Gross Profit | R36: 10765000 | S36: 10644000 | T36: =IFERROR(S36/R36-1,"N/A") -> -0.01124013 | U36: 10183000 | V36: =IFERROR(U36/S36-1,"N/A") -> -0.043310785 | W36: 12025000 | X36: =IFERROR(W36/U36-1,"N/A") -> 0.18088972 | Y36: 12804000 | Z36: =IFERROR(Y36/W36-1,"N/A") -> 0.064781705
A37: Earnings per share | B37: =R52/R95 -> 11.847704 | C37: =S52/S95 -> 3.4285714 | D37: =C37/B37-1 -> -0.71061302 | E37: =U52/T95 -> -0.42016807 | F37: =E37/C37-1 -> -1.122549 | G37: =W52/U95 -> 4.280112 | H37: =G37/E37-1 -> -11.186667 | I37: =Y52/V95 -> 7.5027996 | J37: =I37/G37-1 -> 0.75294466 | K37: Decreasing | L37: <0 | M37: >0 | N37: Increasing | Q37: Royalties & Commission Income | R37: 111000 | S37: 99000 | T37: =IFERROR(S37/R37-1,"N/A") -> -0.10810811 | U37: 83000 | V37: =IFERROR(U37/S37-1,"N/A") -> -0.16161616 | W37: 81000 | X37: =IFERROR(W37/U37-1,"N/A") -> -0.024096386 | Y37: 81000 | Z37: =IFERROR(Y37/W37-1,"N/A") -> 0
A38: P/E ratio | B38: =R96/B37 -> 26.165406 | C38: =S96/C37 -> 37.041667 | D38: =C38/B38-1 -> 0.41567328 | E38: N/A | F38: N/A | G38: =U96/G37 -> 56.073298 | H38: N/A | I38: =V96/I37 -> 25.723731 | J38: =I38/G38-1 -> -0.54124812 | K38: <10 | L38: 10<<<20 | M38: 20<<<<40 | N38: >40 | Q38: Other Operating Income | R38: 149000 | S38: 104000 | T38: =IFERROR(S38/R38-1,"N/A") -> -0.30201342 | U38: 71000 | V38: =IFERROR(U38/S38-1,"N/A") -> -0.31730769 | W38: 174000 | X38: =IFERROR(W38/U38-1,"N/A") -> 1.4507042 | Y38: 41000 | Z38: =IFERROR(Y38/W38-1,"N/A") -> -0.76436782
A39: P/B ratio | B39: =R96/(R21/R95) -> 7.0646931 | C39: =S96/(T21/S95) -> 4.2364979 | D39: =C39/B39-1 -> -0.40032811 | E39: =T96/(W21/T95) -> 6.7050761 | F39: =E39/C39-1 -> 0.58269315 | G39: =U96/(Z21/U95) -> 7.3006135 | H39: =G39/E39-1 -> 0.08881888 | I39: =V96/(AC21/V95) -> 5.9677632 | J39: =I39/G39-1 -> -0.1825669 | K39: <1 | L39: 1<<<<1,5 | M39: 1,5<<<<2 | N39: >2 | Q39: Marketing & Point-of-Sale Exp. | R39: -2082000 | S39: -2430000 | T39: =IFERROR(S39/R39-1,"N/A") -> 0.16714697 | U39: -2528000 | V39: =IFERROR(U39/S39-1,"N/A") -> 0.040329218 | W39: -2841000 | X39: =IFERROR(W39/U39-1,"N/A") -> 0.12381329 | Y39: -3079000 | Z39: =IFERROR(Y39/W39-1,"N/A") -> 0.083773319
A40: Statement of Financial Structure (SFS) (in m) | Q40: Distribution & Selling Exp. | R40: -3943000 | S40: -4384000 | T40: =IFERROR(S40/R40-1,"N/A") -> 0.11184377 | U40: -4521000 | V40: =IFERROR(U40/S40-1,"N/A") -> 0.03125 | W40: -5002000 | X40: =IFERROR(W40/U40-1,"N/A") -> 0.10639239 | Y40: -4948000 | Z40: =IFERROR(Y40/W40-1,"N/A") -> -0.010795682
A41: Working Capital (WC) | B41: =R21+R24-R10 -> 4979000 | C41: =T21+T24-T10 -> 2476000 | D41: =C41/B41-1 -> -0.50271139 | E41: =W21+W24-W10 -> 1766000 | F41: =E41/C41-1 -> -0.28675283 | G41: =Z21+Z24-Z10 -> 2311000 | H41: =G41/E41-1 -> 0.30860702 | I41: =AC21+AC24-AC10 -> 2533000 | J41: =I41/G41-1 -> 0.096062311 | Q41: General & Admin Expenses | R41: -1474000 | S41: -1651000 | T41: =IFERROR(S41/R41-1,"N/A") -> 0.12008141 | U41: -1839000 | V41: =IFERROR(U41/S41-1,"N/A") -> 0.11387038 | W41: -2138000 | X41: =IFERROR(W41/U41-1,"N/A") -> 0.16258836 | Y41: -1885000 | Z41: =IFERROR(Y41/W41-1,"N/A") -> -0.11833489
A42: Working Capital Need (WCN) | B42: =R15-R14-R29+R27 -> 1753000 | C42: =T15-T14-T29+T27 -> 2847000 | D42: =C42/B42-1 -> 0.62407302 | E42: =W15-W14-W29+W27 -> 1640000 | F42: =E42/C42-1 -> -0.42395504 | G42: =Z15-Z14-Z29+Z27 -> 1358000 | H42: =G42/E42-1 -> -0.17195122 | I42: =AC15-AC14-AC29+AC27 -> 2514000 | J42: =I42/G42-1 -> 0.85125184 | K42: <0 | M42: =0 -> 0 | N42: >0 | Q42: EBITDA | R42: 3066000 | S42: 1874000 | T42: =IFERROR(S42/R42-1,"N/A") -> -0.38878017 | U42: 1358000 | V42: =IFERROR(U42/S42-1,"N/A") -> -0.27534685 | W42: 2465000 | X42: =IFERROR(W42/U42-1,"N/A") -> 0.81516937 | Y42: 3124000 | Z42: =IFERROR(Y42/W42-1,"N/A") -> 0.2673428
A43: Net Cash (NC) | B43: =B41-B42 -> 3226000 | C43: =C41-C42 -> -371000 | D43: =C43/B43-1 -> -1.1150031 | E43: =E41-E42 -> 126000 | F43: =E43/C43-1 -> -1.3396226 | G43: =G41-G42 -> 953000 | H43: =G43/E43-1 -> 6.5634921 | I43: =I41-I42 -> 19000 | J43: =I43/G43-1 -> -0.98006296 | K43: >0 | M43: =0 -> 0 | N43: <0 | Q43: Depreciation & Amortisation | R43: -1115000 | S43: -1371000 | T43: =IFERROR(S43/R43-1,"N/A") -> 0.22959641 | U43: -1170000 | V43: =IFERROR(U43/S43-1,"N/A") -> -0.14660832 | W43: -1180000 | X43: =IFERROR(W43/U43-1,"N/A") -> 0.0085470085 | Y43: -1135000 | Z43: =IFERROR(Y43/W43-1,"N/A") -> -0.038135593
A44: Capital Employed | B44: =R10+B42 -> 9946000 | C44: 10.109 | D44: =C44/B44-1 -> -0.99999898 | E44: 9.851 | F44: =E44/C44-1 -> -0.025521812 | G44: 11.41 | H44: =G44/E44-1 -> 0.15825804 | I44: 9.946 | J44: =I44/G44-1 -> -0.1283085 | K44: <0 | M44: =0 -> 0 | N44: >0 | Q44: Operating Profit (EBIT) | R44: 1989000 | S44: 669000 | T44: =IFERROR(S44/R44-1,"N/A") -> -0.66365008 | U44: 268000 | V44: =IFERROR(U44/S44-1,"N/A") -> -0.59940209 | W44: 1337000 | X44: =IFERROR(W44/U44-1,"N/A") -> 3.988806 | Y44: 2060000 | Z44: =IFERROR(Y44/W44-1,"N/A") -> 0.5407629
...
